<?xml version="1.0" ?>
<sdf version="1.9">
  <model name="helios_robot">
    <!-- Base Link -->
    <link name="base_link">
      <visual name="base_link_visual">
        <geometry>
          <box>
            <size>1.0 0.5 0.2</size>
          </box>
        </geometry>
        <material>
          <diffuse>0 0 1 1</diffuse>
        </material>
      </visual>
      <collision name="base_link_collision">
        <geometry>
          <box>
            <size>1.0 0.5 0.2</size>
          </box>
        </geometry>
      </collision>
      <inertial>
        <mass>10.0</mass>
        <inertia>
          <ixx>1.0</ixx>
          <ixy>0.0</ixy>
          <ixz>0.0</ixz>
          <iyy>1.0</iyy>
          <iyz>0.0</iyz>
          <izz>1.0</izz>
        </inertia>
      </inertial>
    </link>

    <!-- Left Wheel -->
    <link name="left_wheel">
      <visual name="left_wheel_visual">
        <geometry>
          <cylinder>
            <radius>0.1</radius>
            <length>0.05</length>
          </cylinder>
        </geometry>
        <material>
          <diffuse>0 0 0 1</diffuse>
        </material>
      </visual>
      <collision name="left_wheel_collision">
        <geometry>
          <cylinder>
            <radius>0.1</radius>
            <length>0.05</length>
          </cylinder>
        </geometry>
      </collision>
      <inertial>
        <mass>1.0</mass>
        <inertia>
          <ixx>0.1</ixx>
          <ixy>0.0</ixy>
          <ixz>0.0</ixz>
          <iyy>0.1</iyy>
          <iyz>0.0</iyz>
          <izz>0.1</izz>
        </inertia>
      </inertial>
    </link>
    <joint name="left_wheel_joint" type="revolute">
      <parent>base_link</parent>
      <child>left_wheel</child>
      <pose>0 0.3 -0.1 1.5708 0 0</pose>
      <axis>
        <xyz>0 1 0</xyz>
        <limit>
          <lower>-1e+16</lower>
          <upper>1e+16</upper>
        </limit>
      </axis>
    </joint>

    <!-- Right Wheel -->
    <link name="right_wheel">
      <visual name="right_wheel_visual">
        <geometry>
          <cylinder>
            <radius>0.1</radius>
            <length>0.05</length>
          </cylinder>
        </geometry>
        <material>
          <diffuse>0 0 0 1</diffuse>
        </material>
      </visual>
      <collision name="right_wheel_collision">
        <geometry>
          <cylinder>
            <radius>0.1</radius>
            <length>0.05</length>
          </cylinder>
        </geometry>
      </collision>
      <inertial>
        <mass>1.0</mass>
        <inertia>
          <ixx>0.1</ixx>
          <ixy>0.0</ixy>
          <ixz>0.0</ixz>
          <iyy>0.1</iyy>
          <iyz>0.0</iyz>
          <izz>0.1</izz>
        </inertia>
      </inertial>
    </link>
    <joint name="right_wheel_joint" type="revolute">
      <parent>base_link</parent>
      <child>right_wheel</child>
      <pose>0 -0.3 -0.1 1.5708 0 0</pose>
      <axis>
        <xyz>0 1 0</xyz>
        <limit>
          <lower>-1e+16</lower>
          <upper>1e+16</upper>
        </limit>
      </axis>
    </joint>

    <!-- Front Caster -->
    <link name="front_caster">
      <visual name="front_caster_visual">
        <geometry>
          <sphere>
            <radius>0.05</radius>
          </sphere>
        </geometry>
        <material>
          <diffuse>0.5 0.5 0.5 1</diffuse>
        </material>
      </visual>
      <collision name="front_caster_collision">
        <geometry>
          <sphere>
            <radius>0.05</radius>
          </sphere>
        </geometry>
      </collision>
      <inertial>
        <mass>0.5</mass>
        <inertia>
          <ixx>0.01</ixx>
          <ixy>0.0</ixy>
          <ixz>0.0</ixz>
          <iyy>0.01</iyy>
          <iyz>0.0</iyz>
          <izz>0.01</izz>
        </inertia>
      </inertial>
    </link>
    <joint name="front_caster_joint" type="fixed">
      <parent>base_link</parent>
      <child>front_caster</child>
      <pose>0.5 0 -0.15 0 0 0</pose>
    </joint>

    <!-- Rear Caster -->
    <link name="rear_caster">
      <visual name="rear_caster_visual">
        <geometry>
          <sphere>
            <radius>0.05</radius>
          </sphere>
        </geometry>
        <material>
          <diffuse>0.5 0.5 0.5 1</diffuse>
        </material>
      </visual>
      <collision name="rear_caster_collision">
        <geometry>
          <sphere>
            <radius>0.05</radius>
          </sphere>
        </geometry>
      </collision>
      <inertial>
        <mass>0.5</mass>
        <inertia>
          <ixx>0.01</ixx>
          <ixy>0.0</ixy>
          <ixz>0.0</ixz>
          <iyy>0.01</iyy>
          <iyz>0.0</iyz>
          <izz>0.01</izz>
        </inertia>
      </inertial>
    </link>
    <joint name="rear_caster_joint" type="fixed">
      <parent>base_link</parent>
      <child>rear_caster</child>
      <pose>-0.5 0 -0.15 0 0 0</pose>
    </joint>

    <!-- Lidar -->
    <link name="lidar_link">
      <visual name="lidar_visual">
        <geometry>
          <cylinder>
            <radius>0.05</radius>
            <length>0.1</length>
          </cylinder>
        </geometry>
        <material>
          <diffuse>1 0 0 1</diffuse>
        </material>
      </visual>
      <sensor name="lidar" type="gpu_lidar">
        <always_on>true</always_on>
        <update_rate>10</update_rate>
        <visualize>true</visualize>
        <pose>0 0 0 0 0 0</pose>
        <ray>
          <scan>
            <horizontal>
              <samples>360</samples>
              <resolution>1</resolution>
              <min_angle>-3.14</min_angle>
              <max_angle>3.14</max_angle>
            </horizontal>
          </scan>
          <range>
            <min>0.1</min>
            <max>10.0</max>
            <resolution>0.01</resolution>
          </range>
        </ray>
        <topic>/lidar</topic>
      </sensor>
    </link>
    <joint name="lidar_joint" type="fixed">
      <parent>base_link</parent>
      <child>lidar_link</child>
      <pose>0.5 0 0.2 0 0 0</pose>
    </joint>

    <!-- Depth Camera -->
    <link name="depth_camera_link">
      <visual name="depth_camera_visual">
        <geometry>
          <box>
            <size>0.05 0.1 0.05</size>
          </box>
        </geometry>
        <material>
          <diffuse>0 1 0 1</diffuse>
        </material>
      </visual>
      <sensor name="depth_camera" type="depth_camera">
        <always_on>true</always_on>
        <update_rate>30</update_rate>
        <visualize>true</visualize>
        <pose>0 0 0 0 0 0</pose>
        <camera>
          <horizontal_fov>1.047</horizontal_fov>
          <image>
            <width>640</width>
            <height>480</height>
            <format>R8G8B8</format>
          </image>
          <clip>
            <near>0.1</near>
            <far>100</far>
          </clip>
          <depth_camera>
            <range>
              <min>0.1</min>
              <max>10.0</max>
            </range>
          </depth_camera>
        </camera>
        <topic>/depth_camera</topic>
      </sensor>
    </link>
    <joint name="depth_camera_joint" type="fixed">
      <parent>base_link</parent>
      <child>depth_camera_link</child>
      <pose>0.4 0 0.3 0 0 0</pose>
    </joint>

    <!-- Differential Drive Plugin -->
    <plugin name="ign_ros2_control" filename="libign_ros2_control-system.so">
      <robot_param>robot_control.yaml</robot_param>
    </plugin>
  </model>
</sdf>