<?xml version="1.0" ?>
<sdf version="1.6">
  <model name="helios">
    <static>false</static>
    
    <!-- Base Link -->
    <link name="base_link">
      <inertial>
        <mass>5.0</mass>
        <inertia>
          <ixx>0.1</ixx>
          <ixy>0</ixy>
          <ixz>0</ixz>
          <iyy>0.1</iyy>
          <iyz>0</iyz>
          <izz>0.1</izz>
        </inertia>
        <pose>0 0 0.1 0 0 0</pose>
      </inertial>
      
      <collision name="base_collision">
        <geometry>
          <box>
            <size>0.5 0.3 0.1</size>
          </box>
        </geometry>
      </collision>
      
      <visual name="base_visual">
        <geometry>
          <box>
            <size>0.5 0.3 0.1</size>
          </box>
        </geometry>
        <material>
          <ambient>0.1 0.1 0.1 1</ambient>
          <diffuse>0.2 0.2 0.8 1</diffuse>
          <specular>0 0 0 1</specular>
          <emissive>0 0 0 1</emissive>
        </material>
      </visual>
      
      <sensor name="imu_sensor" type="imu">
        <pose>0 0 0 0 0 0</pose>
        <always_on>1</always_on>
        <update_rate>100</update_rate>
      </sensor>
    </link>
    
    <!-- Left Wheel -->
    <link name="left_wheel">
      <pose>0.15 0.2 0.05 -1.5707 0 0</pose>
      <inertial>
        <mass>0.5</mass>
        <inertia>
          <ixx>0.001</ixx>
          <ixy>0</ixy>
          <ixz>0</ixz>
          <iyy>0.001</iyy>
          <iyz>0</iyz>
          <izz>0.001</izz>
        </inertia>
      </inertial>
      
      <collision name="left_wheel_collision">
        <geometry>
          <cylinder>
            <radius>0.05</radius>
            <length>0.04</length>
          </cylinder>
        </geometry>
      </collision>
      
      <visual name="left_wheel_visual">
        <geometry>
          <cylinder>
            <radius>0.05</radius>
            <length>0.04</length>
          </cylinder>
        </geometry>
        <material>
          <ambient>0.1 0.1 0.1 1</ambient>
          <diffuse>0.1 0.1 0.1 1</diffuse>
          <specular>0 0 0 1</specular>
          <emissive>0 0 0 1</emissive>
        </material>
      </visual>
    </link>
    
    <!-- Right Wheel -->
    <link name="right_wheel">
      <pose>0.15 -0.2 0.05 -1.5707 0 0</pose>
      <inertial>
        <mass>0.5</mass>
        <inertia>
          <ixx>0.001</ixx>
          <ixy>0</ixy>
          <ixz>0</ixz>
          <iyy>0.001</iyy>
          <iyz>0</iyz>
          <izz>0.001</izz>
        </inertia>
      </inertial>
      
      <collision name="right_wheel_collision">
        <geometry>
          <cylinder>
            <radius>0.05</radius>
            <length>0.04</length>
          </cylinder>
        </geometry>
      </collision>
      
      <visual name="right_wheel_visual">
        <geometry>
          <cylinder>
            <radius>0.05</radius>
            <length>0.04</length>
          </cylinder>
        </geometry>
        <material>
          <ambient>0.1 0.1 0.1 1</ambient>
          <diffuse>0.1 0.1 0.1 1</diffuse>
          <specular>0 0 0 1</specular>
          <emissive>0 0 0 1</emissive>
        </material>
      </visual>
    </link>
    
    <!-- Caster Wheel -->
    <link name="caster">
      <pose>-0.15 0 0.025 0 0 0</pose>
      <inertial>
        <mass>0.1</mass>
        <inertia>
          <ixx>0.0001</ixx>
          <ixy>0</ixy>
          <ixz>0</ixz>
          <iyy>0.0001</iyy>
          <iyz>0</iyz>
          <izz>0.0001</izz>
        </inertia>
      </inertial>
      
      <collision name="caster_collision">
        <geometry>
          <sphere>
            <radius>0.025</radius>
          </sphere>
        </geometry>
        <surface>
          <friction>
            <ode>
              <mu>0.01</mu>
              <mu2>0.01</mu2>
            </ode>
          </friction>
        </surface>
      </collision>
      
      <visual name="caster_visual">
        <geometry>
          <sphere>
            <radius>0.025</radius>
          </sphere>
        </geometry>
        <material>
          <ambient>0.1 0.1 0.1 1</ambient>
          <diffuse>0.1 0.1 0.1 1</diffuse>
          <specular>0 0 0 1</specular>
          <emissive>0 0 0 1</emissive>
        </material>
      </visual>
    </link>
    
    <!-- Add a simple sensor mount -->
    <link name="sensor_mount">
      <pose>0.2 0 0.15 0 0 0</pose>
      <inertial>
        <mass>0.1</mass>
        <inertia>
          <ixx>0.0001</ixx>
          <ixy>0</ixy>
          <ixz>0</ixz>
          <iyy>0.0001</iyy>
          <iyz>0</iyz>
          <izz>0.0001</izz>
        </inertia>
      </inertial>
      
      <collision name="sensor_mount_collision">
        <geometry>
          <box>
            <size>0.05 0.05 0.1</size>
          </box>
        </geometry>
      </collision>
      
      <visual name="sensor_mount_visual">
        <geometry>
          <box>
            <size>0.05 0.05 0.1</size>
          </box>
        </geometry>
        <material>
          <ambient>0.1 0.1 0.1 1</ambient>
          <diffuse>0.3 0.3 0.3 1</diffuse>
          <specular>0 0 0 1</specular>
          <emissive>0 0 0 1</emissive>
        </material>
      </visual>
    </link>
    
    <!-- Joints -->
    <!-- Left wheel joint -->
    <joint name="left_wheel_joint" type="revolute">
      <parent>base_link</parent>
      <child>left_wheel</child>
      <axis>
        <xyz>0 0 1</xyz>
        <limit>
          <effort>10</effort>
          <velocity>10</velocity>
        </limit>
      </axis>
    </joint>
    
    <!-- Right wheel joint -->
    <joint name="right_wheel_joint" type="revolute">
      <parent>base_link</parent>
      <child>right_wheel</child>
      <axis>
        <xyz>0 0 1</xyz>
        <limit>
          <effort>10</effort>
          <velocity>10</velocity>
        </limit>
      </axis>
    </joint>
    
    <!-- Caster joint -->
    <joint name="caster_joint" type="ball">
      <parent>base_link</parent>
      <child>caster</child>
    </joint>
    
    <!-- Sensor mount joint -->
    <joint name="sensor_mount_joint" type="fixed">
      <parent>base_link</parent>
      <child>sensor_mount</child>
    </joint>
    
    <!-- Add Differential Drive Plugin -->
    <plugin name="differential_drive_controller" filename="libgazebo_ros_diff_drive.so">
      <update_rate>100</update_rate>
      <left_joint>left_wheel_joint</left_joint>
      <right_joint>right_wheel_joint</right_joint>
      <wheel_separation>0.4</wheel_separation>
      <wheel_diameter>0.1</wheel_diameter>
      <max_wheel_torque>10</max_wheel_torque>
      <max_wheel_acceleration>1.0</max_wheel_acceleration>
      <command_topic>cmd_vel</command_topic>
      <publish_odom>true</publish_odom>
      <publish_odom_tf>true</publish_odom_tf>
      <publish_wheel_tf>true</publish_wheel_tf>
      <odometry_topic>odom</odometry_topic>
      <odometry_frame>odom</odometry_frame>
      <robot_base_frame>base_link</robot_base_frame>
    </plugin>
    
    <!-- IMU Plugin -->
    <plugin name="imu_plugin" filename="libgazebo_ros_imu.so">
      <alwaysOn>true</alwaysOn>
      <bodyName>base_link</bodyName>
      <topicName>imu</topicName>
      <serviceName>imu_service</serviceName>
      <gaussianNoise>0.0</gaussianNoise>
      <updateRate>50.0</updateRate>
    </plugin>
  </model>
</sdf>